[2025-02-13T10:19:52.162+0000] {taskinstance.py:1956} INFO - Dependencies all met for dep_context=non-requeueable deps ti=<TaskInstance: fetch_and_store_amazon_books.create_table scheduled__2024-07-01T00:00:00+00:00 [queued]>
[2025-02-13T10:19:52.166+0000] {taskinstance.py:1956} INFO - Dependencies all met for dep_context=requeueable deps ti=<TaskInstance: fetch_and_store_amazon_books.create_table scheduled__2024-07-01T00:00:00+00:00 [queued]>
[2025-02-13T10:19:52.166+0000] {taskinstance.py:2170} INFO - Starting attempt 2 of 2
[2025-02-13T10:19:52.172+0000] {taskinstance.py:2191} INFO - Executing <Task(PostgresOperator): create_table> on 2024-07-01 00:00:00+00:00
[2025-02-13T10:19:52.174+0000] {standard_task_runner.py:60} INFO - Started process 295 to run task
[2025-02-13T10:19:52.176+0000] {standard_task_runner.py:87} INFO - Running: ['***', 'tasks', 'run', 'fetch_and_store_amazon_books', 'create_table', 'scheduled__2024-07-01T00:00:00+00:00', '--job-id', '48', '--raw', '--subdir', 'DAGS_FOLDER/app.py', '--cfg-path', '/tmp/tmp3b4304n_']
[2025-02-13T10:19:52.177+0000] {standard_task_runner.py:88} INFO - Job 48: Subtask create_table
[2025-02-13T10:19:52.196+0000] {task_command.py:423} INFO - Running <TaskInstance: fetch_and_store_amazon_books.create_table scheduled__2024-07-01T00:00:00+00:00 [running]> on host d70d224650da
[2025-02-13T10:19:52.224+0000] {taskinstance.py:2480} INFO - Exporting env vars: AIRFLOW_CTX_DAG_OWNER='***' AIRFLOW_CTX_DAG_ID='fetch_and_store_amazon_books' AIRFLOW_CTX_TASK_ID='create_table' AIRFLOW_CTX_EXECUTION_DATE='2024-07-01T00:00:00+00:00' AIRFLOW_CTX_TRY_NUMBER='2' AIRFLOW_CTX_DAG_RUN_ID='scheduled__2024-07-01T00:00:00+00:00'
[2025-02-13T10:19:52.225+0000] {sql.py:276} INFO - Executing: 
        CREATE TABLE IF NOT EXISTS books (
            id SERIAL PRIMARY KEY,
            title TEXT NOT NULL,
            authors TEXT,
            price TEXT,
            rating TEXT
        );
        
[2025-02-13T10:19:52.231+0000] {taskinstance.py:2698} ERROR - Task failed with exception
Traceback (most recent call last):
  File "/home/airflow/.local/lib/python3.8/site-packages/airflow/models/taskinstance.py", line 433, in _execute_task
    result = execute_callable(context=context, **execute_callable_kwargs)
  File "/home/airflow/.local/lib/python3.8/site-packages/airflow/providers/common/sql/operators/sql.py", line 277, in execute
    hook = self.get_db_hook()
  File "/home/airflow/.local/lib/python3.8/site-packages/airflow/providers/common/sql/operators/sql.py", line 188, in get_db_hook
    return self._hook
  File "/usr/local/lib/python3.8/functools.py", line 967, in __get__
    val = self.func(instance)
  File "/home/airflow/.local/lib/python3.8/site-packages/airflow/providers/common/sql/operators/sql.py", line 150, in _hook
    conn = BaseHook.get_connection(conn_id)
  File "/home/airflow/.local/lib/python3.8/site-packages/airflow/hooks/base.py", line 82, in get_connection
    conn = Connection.get_connection_from_secrets(conn_id)
  File "/home/airflow/.local/lib/python3.8/site-packages/airflow/models/connection.py", line 479, in get_connection_from_secrets
    raise AirflowNotFoundException(f"The conn_id `{conn_id}` isn't defined")
airflow.exceptions.AirflowNotFoundException: The conn_id `books_connection` isn't defined
[2025-02-13T10:19:52.232+0000] {taskinstance.py:1138} INFO - Marking task as FAILED. dag_id=fetch_and_store_amazon_books, task_id=create_table, execution_date=20240701T000000, start_date=20250213T101952, end_date=20250213T101952
[2025-02-13T10:19:52.236+0000] {standard_task_runner.py:107} ERROR - Failed to execute job 48 for task create_table (The conn_id `books_connection` isn't defined; 295)
[2025-02-13T10:19:52.272+0000] {local_task_job_runner.py:234} INFO - Task exited with return code 1
[2025-02-13T10:19:52.282+0000] {taskinstance.py:3280} INFO - 0 downstream tasks scheduled from follow-on schedule check
