[2025-02-13T10:35:03.293+0000] {taskinstance.py:1956} INFO - Dependencies all met for dep_context=non-requeueable deps ti=<TaskInstance: fetch_and_store_amazon_books.insert_book_data_into_postgres manual__2025-02-13T10:22:37.289989+00:00 [queued]>
[2025-02-13T10:35:03.296+0000] {taskinstance.py:1956} INFO - Dependencies all met for dep_context=requeueable deps ti=<TaskInstance: fetch_and_store_amazon_books.insert_book_data_into_postgres manual__2025-02-13T10:22:37.289989+00:00 [queued]>
[2025-02-13T10:35:03.296+0000] {taskinstance.py:2170} INFO - Starting attempt 2 of 2
[2025-02-13T10:35:03.302+0000] {taskinstance.py:2191} INFO - Executing <Task(_PythonDecoratedOperator): insert_book_data_into_postgres> on 2025-02-13 10:22:37.289989+00:00
[2025-02-13T10:35:03.304+0000] {standard_task_runner.py:60} INFO - Started process 326 to run task
[2025-02-13T10:35:03.306+0000] {standard_task_runner.py:87} INFO - Running: ['***', 'tasks', 'run', 'fetch_and_store_amazon_books', 'insert_book_data_into_postgres', 'manual__2025-02-13T10:22:37.289989+00:00', '--job-id', '113', '--raw', '--subdir', 'DAGS_FOLDER/app.py', '--cfg-path', '/tmp/tmpdpe0jshw']
[2025-02-13T10:35:03.307+0000] {standard_task_runner.py:88} INFO - Job 113: Subtask insert_book_data_into_postgres
[2025-02-13T10:35:03.326+0000] {task_command.py:423} INFO - Running <TaskInstance: fetch_and_store_amazon_books.insert_book_data_into_postgres manual__2025-02-13T10:22:37.289989+00:00 [running]> on host 7500ade24691
[2025-02-13T10:35:03.352+0000] {taskinstance.py:2480} INFO - Exporting env vars: AIRFLOW_CTX_DAG_OWNER='***' AIRFLOW_CTX_DAG_ID='fetch_and_store_amazon_books' AIRFLOW_CTX_TASK_ID='insert_book_data_into_postgres' AIRFLOW_CTX_EXECUTION_DATE='2025-02-13T10:22:37.289989+00:00' AIRFLOW_CTX_TRY_NUMBER='2' AIRFLOW_CTX_DAG_RUN_ID='manual__2025-02-13T10:22:37.289989+00:00'
[2025-02-13T10:35:03.353+0000] {taskinstance.py:2698} ERROR - Task failed with exception
Traceback (most recent call last):
  File "/home/airflow/.local/lib/python3.8/site-packages/airflow/models/taskinstance.py", line 433, in _execute_task
    result = execute_callable(context=context, **execute_callable_kwargs)
  File "/home/airflow/.local/lib/python3.8/site-packages/airflow/decorators/base.py", line 241, in execute
    return_value = super().execute(context)
  File "/home/airflow/.local/lib/python3.8/site-packages/airflow/operators/python.py", line 199, in execute
    return_value = self.execute_callable()
  File "/home/airflow/.local/lib/python3.8/site-packages/airflow/operators/python.py", line 216, in execute_callable
    return self.python_callable(*self.op_args, **self.op_kwargs)
  File "/opt/airflow/dags/app.py", line 169, in insert_book_data_into_postgres
    raise ValueError("No book data provided for database insertion")
ValueError: No book data provided for database insertion
[2025-02-13T10:35:03.356+0000] {taskinstance.py:1138} INFO - Marking task as FAILED. dag_id=fetch_and_store_amazon_books, task_id=insert_book_data_into_postgres, execution_date=20250213T102237, start_date=20250213T103503, end_date=20250213T103503
[2025-02-13T10:35:03.359+0000] {standard_task_runner.py:107} ERROR - Failed to execute job 113 for task insert_book_data_into_postgres (No book data provided for database insertion; 326)
[2025-02-13T10:35:03.364+0000] {local_task_job_runner.py:234} INFO - Task exited with return code 1
[2025-02-13T10:35:03.371+0000] {taskinstance.py:3280} INFO - 0 downstream tasks scheduled from follow-on schedule check
