[2025-02-13T10:14:49.416+0000] {taskinstance.py:1956} INFO - Dependencies all met for dep_context=non-requeueable deps ti=<TaskInstance: fetch_and_store_amazon_books.create_table scheduled__2024-06-27T00:00:00+00:00 [queued]>
[2025-02-13T10:14:49.424+0000] {taskinstance.py:1956} INFO - Dependencies all met for dep_context=requeueable deps ti=<TaskInstance: fetch_and_store_amazon_books.create_table scheduled__2024-06-27T00:00:00+00:00 [queued]>
[2025-02-13T10:14:49.425+0000] {taskinstance.py:2170} INFO - Starting attempt 1 of 2
[2025-02-13T10:14:49.434+0000] {taskinstance.py:2191} INFO - Executing <Task(PostgresOperator): create_table> on 2024-06-27 00:00:00+00:00
[2025-02-13T10:14:49.438+0000] {standard_task_runner.py:60} INFO - Started process 145 to run task
[2025-02-13T10:14:49.441+0000] {standard_task_runner.py:87} INFO - Running: ['***', 'tasks', 'run', 'fetch_and_store_amazon_books', 'create_table', 'scheduled__2024-06-27T00:00:00+00:00', '--job-id', '21', '--raw', '--subdir', 'DAGS_FOLDER/app.py', '--cfg-path', '/tmp/tmpypie5p21']
[2025-02-13T10:14:49.442+0000] {standard_task_runner.py:88} INFO - Job 21: Subtask create_table
[2025-02-13T10:14:49.488+0000] {task_command.py:423} INFO - Running <TaskInstance: fetch_and_store_amazon_books.create_table scheduled__2024-06-27T00:00:00+00:00 [running]> on host d70d224650da
[2025-02-13T10:14:49.555+0000] {taskinstance.py:2480} INFO - Exporting env vars: AIRFLOW_CTX_DAG_OWNER='***' AIRFLOW_CTX_DAG_ID='fetch_and_store_amazon_books' AIRFLOW_CTX_TASK_ID='create_table' AIRFLOW_CTX_EXECUTION_DATE='2024-06-27T00:00:00+00:00' AIRFLOW_CTX_TRY_NUMBER='1' AIRFLOW_CTX_DAG_RUN_ID='scheduled__2024-06-27T00:00:00+00:00'
[2025-02-13T10:14:49.556+0000] {sql.py:276} INFO - Executing: 
        CREATE TABLE IF NOT EXISTS books (
            id SERIAL PRIMARY KEY,
            title TEXT NOT NULL,
            authors TEXT,
            price TEXT,
            rating TEXT
        );
        
[2025-02-13T10:14:49.572+0000] {taskinstance.py:2698} ERROR - Task failed with exception
Traceback (most recent call last):
  File "/home/airflow/.local/lib/python3.8/site-packages/airflow/models/taskinstance.py", line 433, in _execute_task
    result = execute_callable(context=context, **execute_callable_kwargs)
  File "/home/airflow/.local/lib/python3.8/site-packages/airflow/providers/common/sql/operators/sql.py", line 277, in execute
    hook = self.get_db_hook()
  File "/home/airflow/.local/lib/python3.8/site-packages/airflow/providers/common/sql/operators/sql.py", line 188, in get_db_hook
    return self._hook
  File "/usr/local/lib/python3.8/functools.py", line 967, in __get__
    val = self.func(instance)
  File "/home/airflow/.local/lib/python3.8/site-packages/airflow/providers/common/sql/operators/sql.py", line 150, in _hook
    conn = BaseHook.get_connection(conn_id)
  File "/home/airflow/.local/lib/python3.8/site-packages/airflow/hooks/base.py", line 82, in get_connection
    conn = Connection.get_connection_from_secrets(conn_id)
  File "/home/airflow/.local/lib/python3.8/site-packages/airflow/models/connection.py", line 479, in get_connection_from_secrets
    raise AirflowNotFoundException(f"The conn_id `{conn_id}` isn't defined")
airflow.exceptions.AirflowNotFoundException: The conn_id `books_connection` isn't defined
[2025-02-13T10:14:49.573+0000] {taskinstance.py:1138} INFO - Marking task as UP_FOR_RETRY. dag_id=fetch_and_store_amazon_books, task_id=create_table, execution_date=20240627T000000, start_date=20250213T101449, end_date=20250213T101449
[2025-02-13T10:14:49.580+0000] {standard_task_runner.py:107} ERROR - Failed to execute job 21 for task create_table (The conn_id `books_connection` isn't defined; 145)
[2025-02-13T10:14:49.620+0000] {local_task_job_runner.py:234} INFO - Task exited with return code 1
[2025-02-13T10:14:49.633+0000] {taskinstance.py:3280} INFO - 0 downstream tasks scheduled from follow-on schedule check
